Workbook

Sheet Armes
D1: Stats globales | P1: Capacité Air-Sol (note /5) | X1: Capacité AA (note /5) | AB1: Interception (note /5)
A2: Arme | B2: Source | C2: Type | D2: Méthode ciblage | E2: Pénétration | F2: Explosif (kg éq. TNT) | G2: Coût (M$) | H2: Explosif / M$ | I2: Portée min (m) | J2: Portée max (m) | K2: Vitesse max (m/s) | L2: Vitesse indicielle (/10) | M2: Méthode d'approche | N2: Besoin laser ? (Oui/Non) | O2: Fire and Forget (Oui/Non) | P2: Véhicules légers | Q2: Chars | R2: Bâtiments légers | S2: Gros bâtiments | T2: Bunker | U2: Navire léger | V2: Navire moyen | W2: Porte-avions | X2: Petit avion | Y2: Moyen avion | Z2: Gros avion | AA2: Virage / Agilité | AB2: Signature radar (RCS wiki, valeur brute) | AC2: Signature IR | AD2: Résistance laser | AE2: Difficulté à toucher (site AA complet)
A3: ??? (variante 3) | B3: Jeu de base | C3: Autre / équipement | D3: Optique/TV (opérateur) | E3: 1500 | F3: 2 | G3: 0 | J3: 7000 | K3: =IFERROR(INDEX('Vitesse (calcul)'!$P$21:$P$153,MATCH($A3&"|"&$B3,'Vitesse (calcul)'!$A$21:$A$153,0)),"N/A") -> 597.88 | L3: =IFERROR(INDEX('Vitesse (calcul)'!$S$21:$S$153,MATCH($A3&"|"&$B3,'Vitesse (calcul)'!$A$21:$A$153,0)),"N/A") -> 2.7 | M3: loft 0.2; évasion zigzag 0.1
A4: GS25 | B4: Jeu de base | C4: Autre / équipement | D4: Optique/TV (opérateur) | E4: 1200 | F4: 15 | G4: 0.04 | H4: 375 | I4: 1000 | J4: 10000 | K4: =IFERROR(INDEX('Vitesse (calcul)'!$P$21:$P$153,MATCH($A4&"|"&$B4,'Vitesse (calcul)'!$A$21:$A$153,0)),"N/A") -> N/A | L4: =IFERROR(INDEX('Vitesse (calcul)'!$S$21:$S$153,MATCH($A4&"|"&$B4,'Vitesse (calcul)'!$A$21:$A$153,0)),"N/A") -> N/A | M4: loft 0.5
A5: ??? (variante 1) | B5: Jeu de base | C5: Bombe | D5: Optique (bombe) | E5: 2000 | F5: 11000 | G5: 0 | J5: 10000 | K5: =IFERROR(INDEX('Vitesse (calcul)'!$P$21:$P$153,MATCH($A5&"|"&$B5,'Vitesse (calcul)'!$A$21:$A$153,0)),"N/A") -> N/A | L5: =IFERROR(INDEX('Vitesse (calcul)'!$S$21:$S$153,MATCH($A5&"|"&$B5,'Vitesse (calcul)'!$A$21:$A$153,0)),"N/A") -> N/A
A6: CBO-400 | B6: Jeu de base | C6: Bombe | D6: Optique (bombe) | E6: 0 | F6: 0 | G6: 0.36 | H6: 0 | J6: 5000 | K6: =IFERROR(INDEX('Vitesse (calcul)'!$P$21:$P$153,MATCH($A6&"|"&$B6,'Vitesse (calcul)'!$A$21:$A$153,0)),"N/A") -> N/A | L6: =IFERROR(INDEX('Vitesse (calcul)'!$S$21:$S$153,MATCH($A6&"|"&$B6,'Vitesse (calcul)'!$A$21:$A$153,0)),"N/A") -> N/A | P6: 5 | Q6: 5 | R6: 4 | S6: 3 | T6: 0 | U6: 4 | V6: 3 | W6: 0 | AB6: 0.15 | AC6: 0 | AD6: 4 | AE6: 3
A7: Demolition Bomb | B7: Jeu de base | C7: Bombe | D7: Optique (bombe) | E7: 2000 | F7: 11000 | G7: 0.15 | H7: 73333.333 | J7: 5000 | K7: =IFERROR(INDEX('Vitesse (calcul)'!$P$21:$P$153,MATCH($A7&"|"&$B7,'Vitesse (calcul)'!$A$21:$A$153,0)),"N/A") -> N/A | L7: =IFERROR(INDEX('Vitesse (calcul)'!$S$21:$S$153,MATCH($A7&"|"&$B7,'Vitesse (calcul)'!$A$21:$A$153,0)),"N/A") -> N/A | P7: 5 | Q7: 5 | R7: 5 | S7: 5 | T7: 5 | U7: 5 | V7: 5 | W7: 4 | AB7: 1 | AC7: 0 | AD7: 2 | AE7: 1
A8: GPO-2P Auger | B8: Jeu de base | C8: Bombe | D8: Optique (bombe) | E8: 3000 | F8: 800 | G8: 0.15 | H8: 5333.3333 | J8: 5000 | K8: =IFERROR(INDEX('Vitesse (calcul)'!$P$21:$P$153,MATCH($A8&"|"&$B8,'Vitesse (calcul)'!$A$21:$A$153,0)),"N/A") -> N/A | L8: =IFERROR(INDEX('Vitesse (calcul)'!$S$21:$S$153,MATCH($A8&"|"&$B8,'Vitesse (calcul)'!$A$21:$A$153,0)),"N/A") -> N/A | P8: 5 | Q8: 5 | R8: 5 | S8: 4 | T8: 5 | U8: 5 | V8: 4 | W8: 3 | AB8: 0.2 | AC8: 0 | AD8: 5 | AE8: 1
A9: GPO-500 | B9: Jeu de base | C9: Bombe | D9: Optique (bombe) | E9: 500 | F9: 400 | G9: 0.02 | H9: 20000 | J9: 5000 | K9: =IFERROR(INDEX('Vitesse (calcul)'!$P$21:$P$153,MATCH($A9&"|"&$B9,'Vitesse (calcul)'!$A$21:$A$153,0)),"N/A") -> N/A | L9: =IFERROR(INDEX('Vitesse (calcul)'!$S$21:$S$153,MATCH($A9&"|"&$B9,'Vitesse (calcul)'!$A$21:$A$153,0)),"N/A") -> N/A | P9: 5 | Q9: 4 | R9: 5 | S9: 4 | T9: 5 | U9: 5 | V9: 3 | W9: 2 | AB9: 0.15 | AC9: 0 | AD9: 5 | AE9: 1
A10: PAB-125 | B10: Jeu de base | C10: Bombe | D10: Optique (bombe) | E10: 200 | F10: 100 | G10: 0.01 | H10: 10000 | J10: 4000 | K10: =IFERROR(INDEX('Vitesse (calcul)'!$P$21:$P$153,MATCH($A10&"|"&$B10,'Vitesse (calcul)'!$A$21:$A$153,0)),"N/A") -> N/A | L10: =IFERROR(INDEX('Vitesse (calcul)'!$S$21:$S$153,MATCH($A10&"|"&$B10,'Vitesse (calcul)'!$A$21:$A$153,0)),"N/A") -> N/A | P10: 5 | Q10: 2 | R10: 4 | S10: 3 | T10: 0 | U10: 4 | V10: 2 | W10: 0 | AB10: 0.05 | AC10: 0 | AD10: 1 | AE10: 0
A11: PAB-125HD | B11: Jeu de base | C11: Bombe | D11: Optique (bombe) | E11: 200 | F11: 100 | G11: 0.01 | H11: 10000 | J11: 4000 | K11: =IFERROR(INDEX('Vitesse (calcul)'!$P$21:$P$153,MATCH($A11&"|"&$B11,'Vitesse (calcul)'!$A$21:$A$153,0)),"N/A") -> N/A | L11: =IFERROR(INDEX('Vitesse (calcul)'!$S$21:$S$153,MATCH($A11&"|"&$B11,'Vitesse (calcul)'!$A$21:$A$153,0)),"N/A") -> N/A | P11: 5 | Q11: 2 | R11: 4 | S11: 3 | T11: 0 | U11: 4 | V11: 2 | W11: 0 | AB11: 0.05 | AC11: 0 | AD11: 2 | AE11: 0
A12: PAB-250 | B12: Jeu de base | C12: Bombe | D12: Optique (bombe) | E12: 350 | F12: 200 | G12: 0.015 | H12: 13333.333 | J12: 5000 | K12: =IFERROR(INDEX('Vitesse (calcul)'!$P$21:$P$153,MATCH($A12&"|"&$B12,'Vitesse (calcul)'!$A$21:$A$153,0)),"N/A") -> N/A | L12: =IFERROR(INDEX('Vitesse (calcul)'!$S$21:$S$153,MATCH($A12&"|"&$B12,'Vitesse (calcul)'!$A$21:$A$153,0)),"N/A") -> N/A | P12: 5 | Q12: 3 | R12: 5 | S12: 3 | T12: 2 | U12: 4 | V12: 3 | W12: 1 | AB12: 0.1 | AC12: 0 | AD12: 3 | AE12: 1
A13: GPO-N (1.5kt) | B13: Jeu de base | C13: Bombe nucléaire | D13: Optique (bombe) | E13: 500 | F13: 1500000 | G13: 28 | H13: 53571.429 | J13: 5000 | K13: =IFERROR(INDEX('Vitesse (calcul)'!$P$21:$P$153,MATCH($A13&"|"&$B13,'Vitesse (calcul)'!$A$21:$A$153,0)),"N/A") -> N/A | L13: =IFERROR(INDEX('Vitesse (calcul)'!$S$21:$S$153,MATCH($A13&"|"&$B13,'Vitesse (calcul)'!$A$21:$A$153,0)),"N/A") -> N/A
A14: GPO-N (250kt) | B14: Jeu de base | C14: Bombe nucléaire | D14: Optique (bombe) | E14: 500 | F14: 250000000 | G14: 28 | H14: 8928571.4 | J14: 5000 | K14: =IFERROR(INDEX('Vitesse (calcul)'!$P$21:$P$153,MATCH($A14&"|"&$B14,'Vitesse (calcul)'!$A$21:$A$153,0)),"N/A") -> N/A | L14: =IFERROR(INDEX('Vitesse (calcul)'!$S$21:$S$153,MATCH($A14&"|"&$B14,'Vitesse (calcul)'!$A$21:$A$153,0)),"N/A") -> N/A
A15: GBM-500LR | B15: Jeu de base | C15: Bombe planante guidée | D15: Optique/TV (opérateur) | E15: 250 | F15: 0 | G15: 2.5 | H15: 0 | I15: 1000 | J15: 10000 | K15: =IFERROR(INDEX('Vitesse (calcul)'!$P$21:$P$153,MATCH($A15&"|"&$B15,'Vitesse (calcul)'!$A$21:$A$153,0)),"N/A") -> N/A | L15: =IFERROR(INDEX('Vitesse (calcul)'!$S$21:$S$153,MATCH($A15&"|"&$B15,'Vitesse (calcul)'!$A$21:$A$153,0)),"N/A") -> N/A | M15: datalink; loft 0.05; attaque par le haut (proba 1.0, 1000-50000 m) | P15: 5 | Q15: 5 | R15: 4 | S15: 3 | T15: 0 | U15: 4 | V15: 3 | W15: 0 | AB15: 0.001 | AC15: 0 | AD15: 5 | AE15: 4
A16: PAB-250LR | B16: Jeu de base | C16: Bombe planante guidée | D16: Optique/TV (opérateur) | E16: 350 | F16: 200 | G16: 0.105 | H16: 1904.7619 | I16: 1000 | J16: 10000 | K16: =IFERROR(INDEX('Vitesse (calcul)'!$P$21:$P$153,MATCH($A16&"|"&$B16,'Vitesse (calcul)'!$A$21:$A$153,0)),"N/A") -> N/A | L16: =IFERROR(INDEX('Vitesse (calcul)'!$S$21:$S$153,MATCH($A16&"|"&$B16,'Vitesse (calcul)'!$A$21:$A$153,0)),"N/A") -> N/A | M16: datalink; loft 0.05 | P16: 5 | Q16: 3 | R16: 4 | S16: 3 | T16: 1 | U16: 4 | V16: 3 | W16: 1 | AB16: 0.1 | AC16: 0 | AD16: 3 | AE16: 0
A17: PAB-80LR | B17: Jeu de base | C17: Bombe planante guidée | D17: Optique/TV (opérateur) | E17: 0 | F17: 80 | G17: 0.06 | H17: 1333.3333 | I17: 1000 | J17: 10000 | K17: =IFERROR(INDEX('Vitesse (calcul)'!$P$21:$P$153,MATCH($A17&"|"&$B17,'Vitesse (calcul)'!$A$21:$A$153,0)),"N/A") -> N/A | L17: =IFERROR(INDEX('Vitesse (calcul)'!$S$21:$S$153,MATCH($A17&"|"&$B17,'Vitesse (calcul)'!$A$21:$A$153,0)),"N/A") -> N/A | M17: datalink; loft 0.05 | P17: 5 | Q17: 0 | R17: 4 | S17: 3 | T17: 0 | U17: 4 | V17: 2 | W17: 0 | AB17: 0.001 | AC17: 0 | AD17: 0 | AE17: 0
A18: Radar Jamming Pod | B18: Jeu de base | C18: Brouilleur (nacelle) | G18: 0 | J18: 50000 | K18: =IFERROR(INDEX('Vitesse (calcul)'!$P$21:$P$153,MATCH($A18&"|"&$B18,'Vitesse (calcul)'!$A$21:$A$153,0)),"N/A") -> N/A | L18: =IFERROR(INDEX('Vitesse (calcul)'!$S$21:$S$153,MATCH($A18&"|"&$B18,'Vitesse (calcul)'!$A$21:$A$153,0)),"N/A") -> N/A
A19: 12.7mm Machine Gun | B19: Jeu de base | C19: Canon / mitrailleuse / lance-grenade | E19: 160 | F19: 0 | G19: 3e-06 | H19: 0 | J19: 1800 | K19: =IFERROR(INDEX('Vitesse (calcul)'!$P$21:$P$153,MATCH($A19&"|"&$B19,'Vitesse (calcul)'!$A$21:$A$153,0)),"N/A") -> 850 | L19: =IFERROR(INDEX('Vitesse (calcul)'!$S$21:$S$153,MATCH($A19&"|"&$B19,'Vitesse (calcul)'!$A$21:$A$153,0)),"N/A") -> 4.5 | P19: 1 | Q19: 0 | R19: 0 | S19: 0 | T19: 0 | U19: 0 | V19: 0 | W19: 0 | X19: 0 | Y19: 0 | Z19: 0
A20: 12.7mm Rotary Machine Gun | B20: Jeu de base | C20: Canon / mitrailleuse / lance-grenade | E20: 160 | F20: 0 | G20: 3e-06 | H20: 0 | J20: 2500 | K20: =IFERROR(INDEX('Vitesse (calcul)'!$P$21:$P$153,MATCH($A20&"|"&$B20,'Vitesse (calcul)'!$A$21:$A$153,0)),"N/A") -> 850 | L20: =IFERROR(INDEX('Vitesse (calcul)'!$S$21:$S$153,MATCH($A20&"|"&$B20,'Vitesse (calcul)'!$A$21:$A$153,0)),"N/A") -> 4.5 | P20: 1 | Q20: 0 | R20: 0 | S20: 0 | T20: 0 | U20: 0 | V20: 0 | W20: 0 | X20: 0 | Y20: 0 | Z20: 0
A21: 127mm Cannon | B21: Jeu de base | C21: Canon / mitrailleuse / lance-grenade | E21: 700 | F21: 0.7 | G21: 0.08 | H21: 8.75 | J21: 40000 | K21: =IFERROR(INDEX('Vitesse (calcul)'!$P$21:$P$153,MATCH($A21&"|"&$B21,'Vitesse (calcul)'!$A$21:$A$153,0)),"N/A") -> 850 | L21: =IFERROR(INDEX('Vitesse (calcul)'!$S$21:$S$153,MATCH($A21&"|"&$B21,'Vitesse (calcul)'!$A$21:$A$153,0)),"N/A") -> 4.5 | P21: 4 | Q21: 2 | R21: 1 | S21: 0 | T21: 0 | U21: 1 | V21: 0 | W21: 0
A22: 130mm Cannon | B22: Jeu de base | C22: Canon / mitrailleuse / lance-grenade | E22: 2500 | F22: 5 | G22: 0.003 | H22: 1666.6667 | J22: 4500 | K22: =IFERROR(INDEX('Vitesse (calcul)'!$P$21:$P$153,MATCH($A22&"|"&$B22,'Vitesse (calcul)'!$A$21:$A$153,0)),"N/A") -> 1700 | L22: =IFERROR(INDEX('Vitesse (calcul)'!$S$21:$S$153,MATCH($A22&"|"&$B22,'Vitesse (calcul)'!$A$21:$A$153,0)),"N/A") -> 8.8 | P22: 5 | Q22: 5 | R22: 3 | S22: 2 | T22: 3 | U22: 2 | V22: 1 | W22: 0
A23: 155mm Cannon | B23: Jeu de base | C23: Canon / mitrailleuse / lance-grenade | E23: 700 | F23: 15 | G23: 0.08 | H23: 187.5 | J23: 40000 | K23: =IFERROR(INDEX('Vitesse (calcul)'!$P$21:$P$153,MATCH($A23&"|"&$B23,'Vitesse (calcul)'!$A$21:$A$153,0)),"N/A") -> 850 | L23: =IFERROR(INDEX('Vitesse (calcul)'!$S$21:$S$153,MATCH($A23&"|"&$B23,'Vitesse (calcul)'!$A$21:$A$153,0)),"N/A") -> 4.5 | P23: 5 | Q23: 2 | R23: 3 | S23: 2 | T23: 0 | U23: 3 | V23: 1 | W23: 0
A24: 155mm Railgun | B24: Jeu de base | C24: Canon / mitrailleuse / lance-grenade | E24: 3000 | F24: 20 | G24: 0.03 | H24: 666.66667 | I24: 300 | J24: 50000 | K24: =IFERROR(INDEX('Vitesse (calcul)'!$P$21:$P$153,MATCH($A24&"|"&$B24,'Vitesse (calcul)'!$A$21:$A$153,0)),"N/A") -> 2380 | L24: =IFERROR(INDEX('Vitesse (calcul)'!$S$21:$S$153,MATCH($A24&"|"&$B24,'Vitesse (calcul)'!$A$21:$A$153,0)),"N/A") -> 9.7 | P24: 5 | Q24: 5 | R24: 3 | S24: 2 | T24: 3 | U24: 3 | V24: 2 | W24: 0
A25: 20mm Autocannon | B25: Jeu de base | C25: Canon / mitrailleuse / lance-grenade | E25: 400 | F25: 0.01 | G25: 3e-05 | H25: 333.33333 | J25: 2000 | K25: =IFERROR(INDEX('Vitesse (calcul)'!$P$21:$P$153,MATCH($A25&"|"&$B25,'Vitesse (calcul)'!$A$21:$A$153,0)),"N/A") -> 1100 | L25: =IFERROR(INDEX('Vitesse (calcul)'!$S$21:$S$153,MATCH($A25&"|"&$B25,'Vitesse (calcul)'!$A$21:$A$153,0)),"N/A") -> 7.1 | P25: 3 | Q25: 0 | R25: 0 | S25: 0 | T25: 0 | U25: 0 | V25: 0 | W25: 0 | X25: 1 | Y25: 0 | Z25: 0
A26: 20mm Rotary Cannon (variante 1) | B26: Jeu de base | C26: Canon / mitrailleuse / lance-grenade | E26: 400 | F26: 0.01 | G26: 0.0002 | H26: 50 | J26: 3000 | K26: =IFERROR(INDEX('Vitesse (calcul)'!$P$21:$P$153,MATCH($A26&"|"&$B26,'Vitesse (calcul)'!$A$21:$A$153,0)),"N/A") -> 1100 | L26: =IFERROR(INDEX('Vitesse (calcul)'!$S$21:$S$153,MATCH($A26&"|"&$B26,'Vitesse (calcul)'!$A$21:$A$153,0)),"N/A") -> 7.1 | P26: 3 | Q26: 0 | R26: 0 | S26: 0 | T26: 0 | U26: 0 | V26: 0 | W26: 0 | X26: 1 | Y26: 0 | Z26: 0
A27: 20mm Rotary Cannon (variante 2) | B27: Jeu de base | C27: Canon / mitrailleuse / lance-grenade | E27: 400 | F27: 0.01 | G27: 3e-05 | H27: 333.33333 | J27: 1800 | K27: =IFERROR(INDEX('Vitesse (calcul)'!$P$21:$P$153,MATCH($A27&"|"&$B27,'Vitesse (calcul)'!$A$21:$A$153,0)),"N/A") -> 1100 | L27: =IFERROR(INDEX('Vitesse (calcul)'!$S$21:$S$153,MATCH($A27&"|"&$B27,'Vitesse (calcul)'!$A$21:$A$153,0)),"N/A") -> 7.1 | P27: 3 | Q27: 0 | R27: 0 | S27: 0 | T27: 0 | U27: 0 | V27: 0 | W27: 0 | X27: 1 | Y27: 0 | Z27: 0
A28: 20mm Rotary Cannon (variante 3) | B28: Jeu de base | C28: Canon / mitrailleuse / lance-grenade | E28: 400 | F28: 0.01 | G28: 3e-05 | H28: 333.33333 | J28: 1600 | K28: =IFERROR(INDEX('Vitesse (calcul)'!$P$21:$P$153,MATCH($A28&"|"&$B28,'Vitesse (calcul)'!$A$21:$A$153,0)),"N/A") -> 1040 | L28: =IFERROR(INDEX('Vitesse (calcul)'!$S$21:$S$153,MATCH($A28&"|"&$B28,'Vitesse (calcul)'!$A$21:$A$153,0)),"N/A") -> 5.6 | P28: 3 | Q28: 0 | R28: 0 | S28: 0 | T28: 0 | U28: 0 | V28: 0 | W28: 0 | X28: 1 | Y28: 0 | Z28: 0
A29: 23mm Autocannon | B29: Jeu de base | C29: Canon / mitrailleuse / lance-grenade | E29: 420 | F29: 0.04 | G29: 6e-05 | H29: 666.66667 | J29: 3000 | K29: =IFERROR(INDEX('Vitesse (calcul)'!$P$21:$P$153,MATCH($A29&"|"&$B29,'Vitesse (calcul)'!$A$21:$A$153,0)),"N/A") -> 980 | L29: =IFERROR(INDEX('Vitesse (calcul)'!$S$21:$S$153,MATCH($A29&"|"&$B29,'Vitesse (calcul)'!$A$21:$A$153,0)),"N/A") -> 5.2 | P29: 3 | Q29: 0 | R29: 0 | S29: 0 | T29: 0 | U29: 0 | V29: 0 | W29: 0 | X29: 1 | Y29: 1 | Z29: 0
A30: 25mm Autocannon | B30: Jeu de base | C30: Canon / mitrailleuse / lance-grenade | E30: 420 | F30: 0.04 | G30: 6e-05 | H30: 666.66667 | J30: 2200 | K30: =IFERROR(INDEX('Vitesse (calcul)'!$P$21:$P$153,MATCH($A30&"|"&$B30,'Vitesse (calcul)'!$A$21:$A$153,0)),"N/A") -> 1100 | L30: =IFERROR(INDEX('Vitesse (calcul)'!$S$21:$S$153,MATCH($A30&"|"&$B30,'Vitesse (calcul)'!$A$21:$A$153,0)),"N/A") -> 7.1 | P30: 3 | Q30: 0 | R30: 0 | S30: 0 | T30: 0 | U30: 0 | V30: 0 | W30: 0 | X30: 1 | Y30: 1 | Z30: 0
A31: 25mm Rotary Cannon | B31: Jeu de base | C31: Canon / mitrailleuse / lance-grenade | E31: 500 | F31: 0.04 | G31: 4e-05 | H31: 1000 | J31: 1800 | K31: =IFERROR(INDEX('Vitesse (calcul)'!$P$21:$P$153,MATCH($A31&"|"&$B31,'Vitesse (calcul)'!$A$21:$A$153,0)),"N/A") -> 1100 | L31: =IFERROR(INDEX('Vitesse (calcul)'!$S$21:$S$153,MATCH($A31&"|"&$B31,'Vitesse (calcul)'!$A$21:$A$153,0)),"N/A") -> 7.1 | P31: 4 | Q31: 1 | R31: 0 | S31: 0 | T31: 0 | U31: 0 | V31: 0 | W31: 0 | X31: 1 | Y31: 1 | Z31: 0
A32: 27mm Autocannon | B32: Jeu de base | C32: Canon / mitrailleuse / lance-grenade | E32: 500 | F32: 0.05 | G32: 5e-05 | H32: 1000 | J32: 2000 | K32: =IFERROR(INDEX('Vitesse (calcul)'!$P$21:$P$153,MATCH($A32&"|"&$B32,'Vitesse (calcul)'!$A$21:$A$153,0)),"N/A") -> 1100 | L32: =IFERROR(INDEX('Vitesse (calcul)'!$S$21:$S$153,MATCH($A32&"|"&$B32,'Vitesse (calcul)'!$A$21:$A$153,0)),"N/A") -> 7.1 | P32: 4 | Q32: 1 | R32: 0 | S32: 0 | T32: 0 | U32: 0 | V32: 0 | W32: 0 | X32: 1 | Y32: 1 | Z32: 0
A33: 30mm Cannon | B33: Jeu de base | C33: Canon / mitrailleuse / lance-grenade | E33: 400 | F33: 0.1 | G33: 0.0003 | H33: 333.33333 | J33: 4000 | K33: =IFERROR(INDEX('Vitesse (calcul)'!$P$21:$P$153,MATCH($A33&"|"&$B33,'Vitesse (calcul)'!$A$21:$A$153,0)),"N/A") -> 1200 | L33: =IFERROR(INDEX('Vitesse (calcul)'!$S$21:$S$153,MATCH($A33&"|"&$B33,'Vitesse (calcul)'!$A$21:$A$153,0)),"N/A") -> 7.9 | P33: 3 | Q33: 0 | R33: 0 | S33: 0 | T33: 0 | U33: 0 | V33: 0 | W33: 0 | X33: 1 | Y33: 0 | Z33: 0
A34: 30mm Chaingun | B34: Jeu de base | C34: Canon / mitrailleuse / lance-grenade | E34: 650 | F34: 0.1 | G34: 6e-05 | H34: 1666.6667 | J34: 2000 | K34: =IFERROR(INDEX('Vitesse (calcul)'!$P$21:$P$153,MATCH($A34&"|"&$B34,'Vitesse (calcul)'!$A$21:$A$153,0)),"N/A") -> 805 | L34: =IFERROR(INDEX('Vitesse (calcul)'!$S$21:$S$153,MATCH($A34&"|"&$B34,'Vitesse (calcul)'!$A$21:$A$153,0)),"N/A") -> 3.7 | P34: 4 | Q34: 2 | R34: 0 | S34: 0 | T34: 0 | U34: 0 | V34: 0 | W34: 0 | X34: 1
A35: 30mm Rotary Cannon (variante 1) | B35: Jeu de base | C35: Canon / mitrailleuse / lance-grenade | E35: 650 | F35: 0.03 | G35: 6e-05 | H35: 500 | J35: 3000 | K35: =IFERROR(INDEX('Vitesse (calcul)'!$P$21:$P$153,MATCH($A35&"|"&$B35,'Vitesse (calcul)'!$A$21:$A$153,0)),"N/A") -> 1100 | L35: =IFERROR(INDEX('Vitesse (calcul)'!$S$21:$S$153,MATCH($A35&"|"&$B35,'Vitesse (calcul)'!$A$21:$A$153,0)),"N/A") -> 7.1 | P35: 4 | Q35: 2 | R35: 0 | S35: 0 | T35: 0 | U35: 0 | V35: 0 | W35: 0 | X35: 1 | Y35: 1 | Z35: 0
A36: 30mm Rotary Cannon (variante 2) | B36: Jeu de base | C36: Canon / mitrailleuse / lance-grenade | E36: 500 | F36: 0.1 | G36: 6e-05 | H36: 1666.6667 | J36: 2000 | K36: =IFERROR(INDEX('Vitesse (calcul)'!$P$21:$P$153,MATCH($A36&"|"&$B36,'Vitesse (calcul)'!$A$21:$A$153,0)),"N/A") -> 825 | L36: =IFERROR(INDEX('Vitesse (calcul)'!$S$21:$S$153,MATCH($A36&"|"&$B36,'Vitesse (calcul)'!$A$21:$A$153,0)),"N/A") -> 4 | P36: 4 | Q36: 1 | R36: 0 | S36: 0 | T36: 0 | U36: 0 | V36: 0 | W36: 0 | X36: 1 | Y36: 1 | Z36: 0
A37: 35mm Autocannon | B37: Jeu de base | C37: Canon / mitrailleuse / lance-grenade | E37: 800 | F37: 0.15 | G37: 0.00012 | H37: 1250 | J37: 3000 | K37: =IFERROR(INDEX('Vitesse (calcul)'!$P$21:$P$153,MATCH($A37&"|"&$B37,'Vitesse (calcul)'!$A$21:$A$153,0)),"N/A") -> 1175 | L37: =IFERROR(INDEX('Vitesse (calcul)'!$S$21:$S$153,MATCH($A37&"|"&$B37,'Vitesse (calcul)'!$A$21:$A$153,0)),"N/A") -> 7.7 | P37: 4 | Q37: 3 | R37: 0 | S37: 0 | T37: 0 | U37: 0 | V37: 0 | W37: 0 | X37: 1 | Y37: 1 | Z37: 1
A38: 40mm Cannon | B38: Jeu de base | C38: Canon / mitrailleuse / lance-grenade | E38: 550 | F38: 0.2 | G38: 0.0009 | H38: 222.22222 | J38: 7500 | K38: =IFERROR(INDEX('Vitesse (calcul)'!$P$21:$P$153,MATCH($A38&"|"&$B38,'Vitesse (calcul)'!$A$21:$A$153,0)),"N/A") -> 1100 | L38: =IFERROR(INDEX('Vitesse (calcul)'!$S$21:$S$153,MATCH($A38&"|"&$B38,'Vitesse (calcul)'!$A$21:$A$153,0)),"N/A") -> 7.1 | P38: 4 | Q38: 1 | R38: 0 | S38: 0 | T38: 0 | U38: 0 | V38: 0 | W38: 0 | X38: 1 | Y38: 1 | Z38: 0
A39: 40mm GMG | B39: Jeu de base | C39: Canon / mitrailleuse / lance-grenade | E39: 650 | F39: 0.3 | G39: 0.00012 | H39: 2500 | I39: 30 | J39: 2200 | K39: =IFERROR(INDEX('Vitesse (calcul)'!$P$21:$P$153,MATCH($A39&"|"&$B39,'Vitesse (calcul)'!$A$21:$A$153,0)),"N/A") -> 240 | L39: =IFERROR(INDEX('Vitesse (calcul)'!$S$21:$S$153,MATCH($A39&"|"&$B39,'Vitesse (calcul)'!$A$21:$A$153,0)),"N/A") -> 1.3 | P39: 4 | Q39: 2 | R39: 0 | S39: 0 | T39: 0 | U39: 0 | V39: 0 | W39: 0
A40: 40mm Grenade | B40: Jeu de base | C40: Canon / mitrailleuse / lance-grenade | E40: 650 | F40: 0.3 | G40: 0.00012 | H40: 2500 | I40: 30 | J40: 400 | K40: =IFERROR(INDEX('Vitesse (calcul)'!$P$21:$P$153,MATCH($A40&"|"&$B40,'Vitesse (calcul)'!$A$21:$A$153,0)),"N/A") -> 110 | L40: =IFERROR(INDEX('Vitesse (calcul)'!$S$21:$S$153,MATCH($A40&"|"&$B40,'Vitesse (calcul)'!$A$21:$A$153,0)),"N/A") -> 1.1 | P40: 4 | Q40: 2 | R40: 0 | S40: 0 | T40: 0 | U40: 0 | V40: 0 | W40: 0
...

Sheet Vitesse (calcul)
A1: Vitesse maximale la plus cohérente — calcul, sources et paramètres
A3: Paramètres (texte bleu, modifiables)
A4: Plafond fusée — jeu de base (m/s) | B4: 1250 | C4: Ajusté sur les valeurs « Delta-V » du wiki des missiles dont le calcul dépasse 1 430 m/s.
A5: Plafond fusée — mods (m/s) | B5: 2000 | C5: Valeur déclarée par l'auteur du pack Aryx (Starfall, Zenith).
A6: Coefficient croisière k (m/s par √poussée) | B6: 5.3 | C6: v ≈ k·√poussée, ajusté sur 4 missiles de croisière du wiki.
A7: Durée de poussée minimale « croisière » (s) | B7: 100 | C7: Au-delà, avec une poussée faible, le moteur est de type turboréacteur.
A8: Poussée / poids maximal « croisière » | B8: 1.5
A9: Accélération de la pesanteur g (m/s²) | B9: 9.81
A10: Armes à feu incluses dans la note /10 (1 = oui, 0 = non) | B10: 1 | C10: Mettre 0 pour ne noter que les munitions propulsées (missiles, roquettes).
A12: Règles de choix de la vitesse max (colonne P) :
A13: • Munitions propulsées (poussée connue) : si la vitesse fixée du fichier ET la valeur Delta-V du wiki existent → médiane (fichier ; wiki ; calcul). Sinon wiki, sinon vitesse fixée du fichier, sinon calcul. Le calcul = équation de la fusée (Tsiolkovski) plafonnée, ou k·√poussée pour les missiles de croisière.
A14: • Armes à feu : vitesse initiale (bouche) ; si une vitesse max fixée plus basse existe, on prend la plus basse des deux.
A15: • Bombes, lasers, nacelles, leurres, réservoirs, sous-munitions et équipements : aucune vitesse définie par le jeu (chute libre, vitesse de la lumière ou objet non propulsé) → N/A.
A16: Note /10 : 1 + 9 × (rang centile de la vitesse parmi les armes notées). Les ex æquo reçoivent tous la note du haut du groupe (les missiles plafonnés à 2 000 m/s ont donc 10).
A17: Origine des entrées : fichier NO-stats (poussée, durée, carburant, masse, vitesses fixées) ; page Munitions du wiki Nuclear Option (colonne « Delta-V (Top Speed) », version possiblement antérieure à 0.34).
A20: Clé (Arme|Source) | B20: Arme | C20: Source | D20: Type | E20: Classe | F20: Masse (kg) | G20: Poussée | H20: Durée de poussée (s) | I20: Carburant (kg) | J20: Vitesse initiale / bouche (m/s) | K20: Vitesse max fixée (fichier, m/s) | L20: Vitesse wiki Delta-V (m/s) | M20: Δv Tsiolkovski (m/s) | N20: Régime moteur | O20: Vitesse calculée (m/s) | P20: Vitesse max retenue (m/s) | Q20: Origine de la vitesse | R20: Vitesse prise en compte pour la note (m/s) | S20: Note /10 | T20: Ancienne note /10
A21: =B21&"|"&C21 -> ??? (variante 3)|Jeu de base | B21: ??? (variante 3) | C21: Jeu de base | D21: Autre / équipement | E21: =IF(ISNUMBER(G21),"propulsé",IF(D21="Canon / mitrailleuse / lance-grenade","arme à feu","autre")) -> propulsé | F21: 10 | G21: 31000 | H21: 15 | I21: 3 | J21: 100 | K21: 597.88 | M21: =IF(AND(ISNUMBER(G21),ISNUMBER(H21),ISNUMBER(I21),ISNUMBER(F21)),IF(AND(G21>0,H21>0,I21>0,F21>I21),G21*H21/I21*LN(F21/(F21-I21)),"N/A"),"N/A") -> 55284.616 | N21: =IF(ISNUMBER(M21),IF(AND(H21>=$B$7,G21/(F21*$B$9)<$B$8),"croisière","fusée"),"N/A") -> fusée | O21: =IF(N21="fusée",MIN(M21,IF(C21="Jeu de base",$B$4,$B$5)),IF(N21="croisière",$B$6*SQRT(G21),"N/A")) -> 1250 | P21: =IF(E21="propulsé",IF(ISNUMBER(O21),IF(AND(ISNUMBER(K21),ISNUMBER(L21)),MEDIAN(K21,L21,O21),IF(ISNUMBER(L21),L21,IF(ISNUMBER(K21),K21,O21))),IF(ISNUMBER(K21),K21,"N/A")),IF(E21="arme à feu",IF(ISNUMBER(J21),IF(ISNUMBER(K21),MIN(J21,K21),J21),"N/A"),"N/A")) -> 597.88 | Q21: =IF(NOT(ISNUMBER(P21)),"aucune vitesse définie",IF(E21="arme à feu",IF(AND(ISNUMBER(K21),ISNUMBER(J21),K21<J21),"vitesse max fixée (inférieure à la bouche)","vitesse initiale (bouche)"),IF(AND(ISNUMBER(K21),ISNUMBER(L21)),"médiane fichier / wiki / calcul",IF(ISNUMBER(L21),"wiki Delta-V",IF(ISNUMBER(K21),"vitesse fixée du fichier","calcul ("&N21&IF(AND(N21="fusée",M21>O21),", plafonné","")&")"))))) -> vitesse fixée du fichier | R21: =IF(ISNUMBER(P21),IF(E21="arme à feu",IF($B$10=1,P21,"N/A"),P21),"N/A") -> 597.88 | S21: =IF(ISNUMBER(R21),ROUND(1+9*(SUMPRODUCT(ISNUMBER($R$21:$R$153)*($R$21:$R$153<=R21))-1)/(COUNT($R$21:$R$153)-1),1),"N/A") -> 2.7 | T21: 10
A22: =B22&"|"&C22 -> GS25|Jeu de base | B22: GS25 | C22: Jeu de base | D22: Autre / équipement | E22: =IF(ISNUMBER(G22),"propulsé",IF(D22="Canon / mitrailleuse / lance-grenade","arme à feu","autre")) -> autre | F22: 25 | M22: =IF(AND(ISNUMBER(G22),ISNUMBER(H22),ISNUMBER(I22),ISNUMBER(F22)),IF(AND(G22>0,H22>0,I22>0,F22>I22),G22*H22/I22*LN(F22/(F22-I22)),"N/A"),"N/A") -> N/A | N22: =IF(ISNUMBER(M22),IF(AND(H22>=$B$7,G22/(F22*$B$9)<$B$8),"croisière","fusée"),"N/A") -> N/A | O22: =IF(N22="fusée",MIN(M22,IF(C22="Jeu de base",$B$4,$B$5)),IF(N22="croisière",$B$6*SQRT(G22),"N/A")) -> N/A | P22: =IF(E22="propulsé",IF(ISNUMBER(O22),IF(AND(ISNUMBER(K22),ISNUMBER(L22)),MEDIAN(K22,L22,O22),IF(ISNUMBER(L22),L22,IF(ISNUMBER(K22),K22,O22))),IF(ISNUMBER(K22),K22,"N/A")),IF(E22="arme à feu",IF(ISNUMBER(J22),IF(ISNUMBER(K22),MIN(J22,K22),J22),"N/A"),"N/A")) -> N/A | Q22: =IF(NOT(ISNUMBER(P22)),"aucune vitesse définie",IF(E22="arme à feu",IF(AND(ISNUMBER(K22),ISNUMBER(J22),K22<J22),"vitesse max fixée (inférieure à la bouche)","vitesse initiale (bouche)"),IF(AND(ISNUMBER(K22),ISNUMBER(L22)),"médiane fichier / wiki / calcul",IF(ISNUMBER(L22),"wiki Delta-V",IF(ISNUMBER(K22),"vitesse fixée du fichier","calcul ("&N22&IF(AND(N22="fusée",M22>O22),", plafonné","")&")"))))) -> aucune vitesse définie | R22: =IF(ISNUMBER(P22),IF(E22="arme à feu",IF($B$10=1,P22,"N/A"),P22),"N/A") -> N/A | S22: =IF(ISNUMBER(R22),ROUND(1+9*(SUMPRODUCT(ISNUMBER($R$21:$R$153)*($R$21:$R$153<=R22))-1)/(COUNT($R$21:$R$153)-1),1),"N/A") -> N/A
A23: =B23&"|"&C23 -> ??? (variante 1)|Jeu de base | B23: ??? (variante 1) | C23: Jeu de base | D23: Bombe | E23: =IF(ISNUMBER(G23),"propulsé",IF(D23="Canon / mitrailleuse / lance-grenade","arme à feu","autre")) -> autre | F23: 10 | J23: 100 | M23: =IF(AND(ISNUMBER(G23),ISNUMBER(H23),ISNUMBER(I23),ISNUMBER(F23)),IF(AND(G23>0,H23>0,I23>0,F23>I23),G23*H23/I23*LN(F23/(F23-I23)),"N/A"),"N/A") -> N/A | N23: =IF(ISNUMBER(M23),IF(AND(H23>=$B$7,G23/(F23*$B$9)<$B$8),"croisière","fusée"),"N/A") -> N/A | O23: =IF(N23="fusée",MIN(M23,IF(C23="Jeu de base",$B$4,$B$5)),IF(N23="croisière",$B$6*SQRT(G23),"N/A")) -> N/A | P23: =IF(E23="propulsé",IF(ISNUMBER(O23),IF(AND(ISNUMBER(K23),ISNUMBER(L23)),MEDIAN(K23,L23,O23),IF(ISNUMBER(L23),L23,IF(ISNUMBER(K23),K23,O23))),IF(ISNUMBER(K23),K23,"N/A")),IF(E23="arme à feu",IF(ISNUMBER(J23),IF(ISNUMBER(K23),MIN(J23,K23),J23),"N/A"),"N/A")) -> N/A | Q23: =IF(NOT(ISNUMBER(P23)),"aucune vitesse définie",IF(E23="arme à feu",IF(AND(ISNUMBER(K23),ISNUMBER(J23),K23<J23),"vitesse max fixée (inférieure à la bouche)","vitesse initiale (bouche)"),IF(AND(ISNUMBER(K23),ISNUMBER(L23)),"médiane fichier / wiki / calcul",IF(ISNUMBER(L23),"wiki Delta-V",IF(ISNUMBER(K23),"vitesse fixée du fichier","calcul ("&N23&IF(AND(N23="fusée",M23>O23),", plafonné","")&")"))))) -> aucune vitesse définie | R23: =IF(ISNUMBER(P23),IF(E23="arme à feu",IF($B$10=1,P23,"N/A"),P23),"N/A") -> N/A | S23: =IF(ISNUMBER(R23),ROUND(1+9*(SUMPRODUCT(ISNUMBER($R$21:$R$153)*($R$21:$R$153<=R23))-1)/(COUNT($R$21:$R$153)-1),1),"N/A") -> N/A
A24: =B24&"|"&C24 -> CBO-400|Jeu de base | B24: CBO-400 | C24: Jeu de base | D24: Bombe | E24: =IF(ISNUMBER(G24),"propulsé",IF(D24="Canon / mitrailleuse / lance-grenade","arme à feu","autre")) -> autre | F24: 400 | M24: =IF(AND(ISNUMBER(G24),ISNUMBER(H24),ISNUMBER(I24),ISNUMBER(F24)),IF(AND(G24>0,H24>0,I24>0,F24>I24),G24*H24/I24*LN(F24/(F24-I24)),"N/A"),"N/A") -> N/A | N24: =IF(ISNUMBER(M24),IF(AND(H24>=$B$7,G24/(F24*$B$9)<$B$8),"croisière","fusée"),"N/A") -> N/A | O24: =IF(N24="fusée",MIN(M24,IF(C24="Jeu de base",$B$4,$B$5)),IF(N24="croisière",$B$6*SQRT(G24),"N/A")) -> N/A | P24: =IF(E24="propulsé",IF(ISNUMBER(O24),IF(AND(ISNUMBER(K24),ISNUMBER(L24)),MEDIAN(K24,L24,O24),IF(ISNUMBER(L24),L24,IF(ISNUMBER(K24),K24,O24))),IF(ISNUMBER(K24),K24,"N/A")),IF(E24="arme à feu",IF(ISNUMBER(J24),IF(ISNUMBER(K24),MIN(J24,K24),J24),"N/A"),"N/A")) -> N/A | Q24: =IF(NOT(ISNUMBER(P24)),"aucune vitesse définie",IF(E24="arme à feu",IF(AND(ISNUMBER(K24),ISNUMBER(J24),K24<J24),"vitesse max fixée (inférieure à la bouche)","vitesse initiale (bouche)"),IF(AND(ISNUMBER(K24),ISNUMBER(L24)),"médiane fichier / wiki / calcul",IF(ISNUMBER(L24),"wiki Delta-V",IF(ISNUMBER(K24),"vitesse fixée du fichier","calcul ("&N24&IF(AND(N24="fusée",M24>O24),", plafonné","")&")"))))) -> aucune vitesse définie | R24: =IF(ISNUMBER(P24),IF(E24="arme à feu",IF($B$10=1,P24,"N/A"),P24),"N/A") -> N/A | S24: =IF(ISNUMBER(R24),ROUND(1+9*(SUMPRODUCT(ISNUMBER($R$21:$R$153)*($R$21:$R$153<=R24))-1)/(COUNT($R$21:$R$153)-1),1),"N/A") -> N/A
A25: =B25&"|"&C25 -> Demolition Bomb|Jeu de base | B25: Demolition Bomb | C25: Jeu de base | D25: Bombe | E25: =IF(ISNUMBER(G25),"propulsé",IF(D25="Canon / mitrailleuse / lance-grenade","arme à feu","autre")) -> autre | F25: 10000 | M25: =IF(AND(ISNUMBER(G25),ISNUMBER(H25),ISNUMBER(I25),ISNUMBER(F25)),IF(AND(G25>0,H25>0,I25>0,F25>I25),G25*H25/I25*LN(F25/(F25-I25)),"N/A"),"N/A") -> N/A | N25: =IF(ISNUMBER(M25),IF(AND(H25>=$B$7,G25/(F25*$B$9)<$B$8),"croisière","fusée"),"N/A") -> N/A | O25: =IF(N25="fusée",MIN(M25,IF(C25="Jeu de base",$B$4,$B$5)),IF(N25="croisière",$B$6*SQRT(G25),"N/A")) -> N/A | P25: =IF(E25="propulsé",IF(ISNUMBER(O25),IF(AND(ISNUMBER(K25),ISNUMBER(L25)),MEDIAN(K25,L25,O25),IF(ISNUMBER(L25),L25,IF(ISNUMBER(K25),K25,O25))),IF(ISNUMBER(K25),K25,"N/A")),IF(E25="arme à feu",IF(ISNUMBER(J25),IF(ISNUMBER(K25),MIN(J25,K25),J25),"N/A"),"N/A")) -> N/A | Q25: =IF(NOT(ISNUMBER(P25)),"aucune vitesse définie",IF(E25="arme à feu",IF(AND(ISNUMBER(K25),ISNUMBER(J25),K25<J25),"vitesse max fixée (inférieure à la bouche)","vitesse initiale (bouche)"),IF(AND(ISNUMBER(K25),ISNUMBER(L25)),"médiane fichier / wiki / calcul",IF(ISNUMBER(L25),"wiki Delta-V",IF(ISNUMBER(K25),"vitesse fixée du fichier","calcul ("&N25&IF(AND(N25="fusée",M25>O25),", plafonné","")&")"))))) -> aucune vitesse définie | R25: =IF(ISNUMBER(P25),IF(E25="arme à feu",IF($B$10=1,P25,"N/A"),P25),"N/A") -> N/A | S25: =IF(ISNUMBER(R25),ROUND(1+9*(SUMPRODUCT(ISNUMBER($R$21:$R$153)*($R$21:$R$153<=R25))-1)/(COUNT($R$21:$R$153)-1),1),"N/A") -> N/A
A26: =B26&"|"&C26 -> GPO-2P Auger|Jeu de base | B26: GPO-2P Auger | C26: Jeu de base | D26: Bombe | E26: =IF(ISNUMBER(G26),"propulsé",IF(D26="Canon / mitrailleuse / lance-grenade","arme à feu","autre")) -> autre | F26: 1000 | M26: =IF(AND(ISNUMBER(G26),ISNUMBER(H26),ISNUMBER(I26),ISNUMBER(F26)),IF(AND(G26>0,H26>0,I26>0,F26>I26),G26*H26/I26*LN(F26/(F26-I26)),"N/A"),"N/A") -> N/A | N26: =IF(ISNUMBER(M26),IF(AND(H26>=$B$7,G26/(F26*$B$9)<$B$8),"croisière","fusée"),"N/A") -> N/A | O26: =IF(N26="fusée",MIN(M26,IF(C26="Jeu de base",$B$4,$B$5)),IF(N26="croisière",$B$6*SQRT(G26),"N/A")) -> N/A | P26: =IF(E26="propulsé",IF(ISNUMBER(O26),IF(AND(ISNUMBER(K26),ISNUMBER(L26)),MEDIAN(K26,L26,O26),IF(ISNUMBER(L26),L26,IF(ISNUMBER(K26),K26,O26))),IF(ISNUMBER(K26),K26,"N/A")),IF(E26="arme à feu",IF(ISNUMBER(J26),IF(ISNUMBER(K26),MIN(J26,K26),J26),"N/A"),"N/A")) -> N/A | Q26: =IF(NOT(ISNUMBER(P26)),"aucune vitesse définie",IF(E26="arme à feu",IF(AND(ISNUMBER(K26),ISNUMBER(J26),K26<J26),"vitesse max fixée (inférieure à la bouche)","vitesse initiale (bouche)"),IF(AND(ISNUMBER(K26),ISNUMBER(L26)),"médiane fichier / wiki / calcul",IF(ISNUMBER(L26),"wiki Delta-V",IF(ISNUMBER(K26),"vitesse fixée du fichier","calcul ("&N26&IF(AND(N26="fusée",M26>O26),", plafonné","")&")"))))) -> aucune vitesse définie | R26: =IF(ISNUMBER(P26),IF(E26="arme à feu",IF($B$10=1,P26,"N/A"),P26),"N/A") -> N/A | S26: =IF(ISNUMBER(R26),ROUND(1+9*(SUMPRODUCT(ISNUMBER($R$21:$R$153)*($R$21:$R$153<=R26))-1)/(COUNT($R$21:$R$153)-1),1),"N/A") -> N/A
A27: =B27&"|"&C27 -> GPO-500|Jeu de base | B27: GPO-500 | C27: Jeu de base | D27: Bombe | E27: =IF(ISNUMBER(G27),"propulsé",IF(D27="Canon / mitrailleuse / lance-grenade","arme à feu","autre")) -> autre | F27: 500 | M27: =IF(AND(ISNUMBER(G27),ISNUMBER(H27),ISNUMBER(I27),ISNUMBER(F27)),IF(AND(G27>0,H27>0,I27>0,F27>I27),G27*H27/I27*LN(F27/(F27-I27)),"N/A"),"N/A") -> N/A | N27: =IF(ISNUMBER(M27),IF(AND(H27>=$B$7,G27/(F27*$B$9)<$B$8),"croisière","fusée"),"N/A") -> N/A | O27: =IF(N27="fusée",MIN(M27,IF(C27="Jeu de base",$B$4,$B$5)),IF(N27="croisière",$B$6*SQRT(G27),"N/A")) -> N/A | P27: =IF(E27="propulsé",IF(ISNUMBER(O27),IF(AND(ISNUMBER(K27),ISNUMBER(L27)),MEDIAN(K27,L27,O27),IF(ISNUMBER(L27),L27,IF(ISNUMBER(K27),K27,O27))),IF(ISNUMBER(K27),K27,"N/A")),IF(E27="arme à feu",IF(ISNUMBER(J27),IF(ISNUMBER(K27),MIN(J27,K27),J27),"N/A"),"N/A")) -> N/A | Q27: =IF(NOT(ISNUMBER(P27)),"aucune vitesse définie",IF(E27="arme à feu",IF(AND(ISNUMBER(K27),ISNUMBER(J27),K27<J27),"vitesse max fixée (inférieure à la bouche)","vitesse initiale (bouche)"),IF(AND(ISNUMBER(K27),ISNUMBER(L27)),"médiane fichier / wiki / calcul",IF(ISNUMBER(L27),"wiki Delta-V",IF(ISNUMBER(K27),"vitesse fixée du fichier","calcul ("&N27&IF(AND(N27="fusée",M27>O27),", plafonné","")&")"))))) -> aucune vitesse définie | R27: =IF(ISNUMBER(P27),IF(E27="arme à feu",IF($B$10=1,P27,"N/A"),P27),"N/A") -> N/A | S27: =IF(ISNUMBER(R27),ROUND(1+9*(SUMPRODUCT(ISNUMBER($R$21:$R$153)*($R$21:$R$153<=R27))-1)/(COUNT($R$21:$R$153)-1),1),"N/A") -> N/A
A28: =B28&"|"&C28 -> PAB-125|Jeu de base | B28: PAB-125 | C28: Jeu de base | D28: Bombe | E28: =IF(ISNUMBER(G28),"propulsé",IF(D28="Canon / mitrailleuse / lance-grenade","arme à feu","autre")) -> autre | F28: 125 | M28: =IF(AND(ISNUMBER(G28),ISNUMBER(H28),ISNUMBER(I28),ISNUMBER(F28)),IF(AND(G28>0,H28>0,I28>0,F28>I28),G28*H28/I28*LN(F28/(F28-I28)),"N/A"),"N/A") -> N/A | N28: =IF(ISNUMBER(M28),IF(AND(H28>=$B$7,G28/(F28*$B$9)<$B$8),"croisière","fusée"),"N/A") -> N/A | O28: =IF(N28="fusée",MIN(M28,IF(C28="Jeu de base",$B$4,$B$5)),IF(N28="croisière",$B$6*SQRT(G28),"N/A")) -> N/A | P28: =IF(E28="propulsé",IF(ISNUMBER(O28),IF(AND(ISNUMBER(K28),ISNUMBER(L28)),MEDIAN(K28,L28,O28),IF(ISNUMBER(L28),L28,IF(ISNUMBER(K28),K28,O28))),IF(ISNUMBER(K28),K28,"N/A")),IF(E28="arme à feu",IF(ISNUMBER(J28),IF(ISNUMBER(K28),MIN(J28,K28),J28),"N/A"),"N/A")) -> N/A | Q28: =IF(NOT(ISNUMBER(P28)),"aucune vitesse définie",IF(E28="arme à feu",IF(AND(ISNUMBER(K28),ISNUMBER(J28),K28<J28),"vitesse max fixée (inférieure à la bouche)","vitesse initiale (bouche)"),IF(AND(ISNUMBER(K28),ISNUMBER(L28)),"médiane fichier / wiki / calcul",IF(ISNUMBER(L28),"wiki Delta-V",IF(ISNUMBER(K28),"vitesse fixée du fichier","calcul ("&N28&IF(AND(N28="fusée",M28>O28),", plafonné","")&")"))))) -> aucune vitesse définie | R28: =IF(ISNUMBER(P28),IF(E28="arme à feu",IF($B$10=1,P28,"N/A"),P28),"N/A") -> N/A | S28: =IF(ISNUMBER(R28),ROUND(1+9*(SUMPRODUCT(ISNUMBER($R$21:$R$153)*($R$21:$R$153<=R28))-1)/(COUNT($R$21:$R$153)-1),1),"N/A") -> N/A
A29: =B29&"|"&C29 -> PAB-125HD|Jeu de base | B29: PAB-125HD | C29: Jeu de base | D29: Bombe | E29: =IF(ISNUMBER(G29),"propulsé",IF(D29="Canon / mitrailleuse / lance-grenade","arme à feu","autre")) -> autre | F29: 125 | M29: =IF(AND(ISNUMBER(G29),ISNUMBER(H29),ISNUMBER(I29),ISNUMBER(F29)),IF(AND(G29>0,H29>0,I29>0,F29>I29),G29*H29/I29*LN(F29/(F29-I29)),"N/A"),"N/A") -> N/A | N29: =IF(ISNUMBER(M29),IF(AND(H29>=$B$7,G29/(F29*$B$9)<$B$8),"croisière","fusée"),"N/A") -> N/A | O29: =IF(N29="fusée",MIN(M29,IF(C29="Jeu de base",$B$4,$B$5)),IF(N29="croisière",$B$6*SQRT(G29),"N/A")) -> N/A | P29: =IF(E29="propulsé",IF(ISNUMBER(O29),IF(AND(ISNUMBER(K29),ISNUMBER(L29)),MEDIAN(K29,L29,O29),IF(ISNUMBER(L29),L29,IF(ISNUMBER(K29),K29,O29))),IF(ISNUMBER(K29),K29,"N/A")),IF(E29="arme à feu",IF(ISNUMBER(J29),IF(ISNUMBER(K29),MIN(J29,K29),J29),"N/A"),"N/A")) -> N/A | Q29: =IF(NOT(ISNUMBER(P29)),"aucune vitesse définie",IF(E29="arme à feu",IF(AND(ISNUMBER(K29),ISNUMBER(J29),K29<J29),"vitesse max fixée (inférieure à la bouche)","vitesse initiale (bouche)"),IF(AND(ISNUMBER(K29),ISNUMBER(L29)),"médiane fichier / wiki / calcul",IF(ISNUMBER(L29),"wiki Delta-V",IF(ISNUMBER(K29),"vitesse fixée du fichier","calcul ("&N29&IF(AND(N29="fusée",M29>O29),", plafonné","")&")"))))) -> aucune vitesse définie | R29: =IF(ISNUMBER(P29),IF(E29="arme à feu",IF($B$10=1,P29,"N/A"),P29),"N/A") -> N/A | S29: =IF(ISNUMBER(R29),ROUND(1+9*(SUMPRODUCT(ISNUMBER($R$21:$R$153)*($R$21:$R$153<=R29))-1)/(COUNT($R$21:$R$153)-1),1),"N/A") -> N/A
A30: =B30&"|"&C30 -> PAB-250|Jeu de base | B30: PAB-250 | C30: Jeu de base | D30: Bombe | E30: =IF(ISNUMBER(G30),"propulsé",IF(D30="Canon / mitrailleuse / lance-grenade","arme à feu","autre")) -> autre | F30: 250 | M30: =IF(AND(ISNUMBER(G30),ISNUMBER(H30),ISNUMBER(I30),ISNUMBER(F30)),IF(AND(G30>0,H30>0,I30>0,F30>I30),G30*H30/I30*LN(F30/(F30-I30)),"N/A"),"N/A") -> N/A | N30: =IF(ISNUMBER(M30),IF(AND(H30>=$B$7,G30/(F30*$B$9)<$B$8),"croisière","fusée"),"N/A") -> N/A | O30: =IF(N30="fusée",MIN(M30,IF(C30="Jeu de base",$B$4,$B$5)),IF(N30="croisière",$B$6*SQRT(G30),"N/A")) -> N/A | P30: =IF(E30="propulsé",IF(ISNUMBER(O30),IF(AND(ISNUMBER(K30),ISNUMBER(L30)),MEDIAN(K30,L30,O30),IF(ISNUMBER(L30),L30,IF(ISNUMBER(K30),K30,O30))),IF(ISNUMBER(K30),K30,"N/A")),IF(E30="arme à feu",IF(ISNUMBER(J30),IF(ISNUMBER(K30),MIN(J30,K30),J30),"N/A"),"N/A")) -> N/A | Q30: =IF(NOT(ISNUMBER(P30)),"aucune vitesse définie",IF(E30="arme à feu",IF(AND(ISNUMBER(K30),ISNUMBER(J30),K30<J30),"vitesse max fixée (inférieure à la bouche)","vitesse initiale (bouche)"),IF(AND(ISNUMBER(K30),ISNUMBER(L30)),"médiane fichier / wiki / calcul",IF(ISNUMBER(L30),"wiki Delta-V",IF(ISNUMBER(K30),"vitesse fixée du fichier","calcul ("&N30&IF(AND(N30="fusée",M30>O30),", plafonné","")&")"))))) -> aucune vitesse définie | R30: =IF(ISNUMBER(P30),IF(E30="arme à feu",IF($B$10=1,P30,"N/A"),P30),"N/A") -> N/A | S30: =IF(ISNUMBER(R30),ROUND(1+9*(SUMPRODUCT(ISNUMBER($R$21:$R$153)*($R$21:$R$153<=R30))-1)/(COUNT($R$21:$R$153)-1),1),"N/A") -> N/A
A31: =B31&"|"&C31 -> GPO-N (1.5kt)|Jeu de base | B31: GPO-N (1.5kt) | C31: Jeu de base | D31: Bombe nucléaire | E31: =IF(ISNUMBER(G31),"propulsé",IF(D31="Canon / mitrailleuse / lance-grenade","arme à feu","autre")) -> autre | F31: 400 | M31: =IF(AND(ISNUMBER(G31),ISNUMBER(H31),ISNUMBER(I31),ISNUMBER(F31)),IF(AND(G31>0,H31>0,I31>0,F31>I31),G31*H31/I31*LN(F31/(F31-I31)),"N/A"),"N/A") -> N/A | N31: =IF(ISNUMBER(M31),IF(AND(H31>=$B$7,G31/(F31*$B$9)<$B$8),"croisière","fusée"),"N/A") -> N/A | O31: =IF(N31="fusée",MIN(M31,IF(C31="Jeu de base",$B$4,$B$5)),IF(N31="croisière",$B$6*SQRT(G31),"N/A")) -> N/A | P31: =IF(E31="propulsé",IF(ISNUMBER(O31),IF(AND(ISNUMBER(K31),ISNUMBER(L31)),MEDIAN(K31,L31,O31),IF(ISNUMBER(L31),L31,IF(ISNUMBER(K31),K31,O31))),IF(ISNUMBER(K31),K31,"N/A")),IF(E31="arme à feu",IF(ISNUMBER(J31),IF(ISNUMBER(K31),MIN(J31,K31),J31),"N/A"),"N/A")) -> N/A | Q31: =IF(NOT(ISNUMBER(P31)),"aucune vitesse définie",IF(E31="arme à feu",IF(AND(ISNUMBER(K31),ISNUMBER(J31),K31<J31),"vitesse max fixée (inférieure à la bouche)","vitesse initiale (bouche)"),IF(AND(ISNUMBER(K31),ISNUMBER(L31)),"médiane fichier / wiki / calcul",IF(ISNUMBER(L31),"wiki Delta-V",IF(ISNUMBER(K31),"vitesse fixée du fichier","calcul ("&N31&IF(AND(N31="fusée",M31>O31),", plafonné","")&")"))))) -> aucune vitesse définie | R31: =IF(ISNUMBER(P31),IF(E31="arme à feu",IF($B$10=1,P31,"N/A"),P31),"N/A") -> N/A | S31: =IF(ISNUMBER(R31),ROUND(1+9*(SUMPRODUCT(ISNUMBER($R$21:$R$153)*($R$21:$R$153<=R31))-1)/(COUNT($R$21:$R$153)-1),1),"N/A") -> N/A
A32: =B32&"|"&C32 -> GPO-N (250kt)|Jeu de base | B32: GPO-N (250kt) | C32: Jeu de base | D32: Bombe nucléaire | E32: =IF(ISNUMBER(G32),"propulsé",IF(D32="Canon / mitrailleuse / lance-grenade","arme à feu","autre")) -> autre | F32: 400 | M32: =IF(AND(ISNUMBER(G32),ISNUMBER(H32),ISNUMBER(I32),ISNUMBER(F32)),IF(AND(G32>0,H32>0,I32>0,F32>I32),G32*H32/I32*LN(F32/(F32-I32)),"N/A"),"N/A") -> N/A | N32: =IF(ISNUMBER(M32),IF(AND(H32>=$B$7,G32/(F32*$B$9)<$B$8),"croisière","fusée"),"N/A") -> N/A | O32: =IF(N32="fusée",MIN(M32,IF(C32="Jeu de base",$B$4,$B$5)),IF(N32="croisière",$B$6*SQRT(G32),"N/A")) -> N/A | P32: =IF(E32="propulsé",IF(ISNUMBER(O32),IF(AND(ISNUMBER(K32),ISNUMBER(L32)),MEDIAN(K32,L32,O32),IF(ISNUMBER(L32),L32,IF(ISNUMBER(K32),K32,O32))),IF(ISNUMBER(K32),K32,"N/A")),IF(E32="arme à feu",IF(ISNUMBER(J32),IF(ISNUMBER(K32),MIN(J32,K32),J32),"N/A"),"N/A")) -> N/A | Q32: =IF(NOT(ISNUMBER(P32)),"aucune vitesse définie",IF(E32="arme à feu",IF(AND(ISNUMBER(K32),ISNUMBER(J32),K32<J32),"vitesse max fixée (inférieure à la bouche)","vitesse initiale (bouche)"),IF(AND(ISNUMBER(K32),ISNUMBER(L32)),"médiane fichier / wiki / calcul",IF(ISNUMBER(L32),"wiki Delta-V",IF(ISNUMBER(K32),"vitesse fixée du fichier","calcul ("&N32&IF(AND(N32="fusée",M32>O32),", plafonné","")&")"))))) -> aucune vitesse définie | R32: =IF(ISNUMBER(P32),IF(E32="arme à feu",IF($B$10=1,P32,"N/A"),P32),"N/A") -> N/A | S32: =IF(ISNUMBER(R32),ROUND(1+9*(SUMPRODUCT(ISNUMBER($R$21:$R$153)*($R$21:$R$153<=R32))-1)/(COUNT($R$21:$R$153)-1),1),"N/A") -> N/A
A33: =B33&"|"&C33 -> GBM-500LR|Jeu de base | B33: GBM-500LR | C33: Jeu de base | D33: Bombe planante guidée | E33: =IF(ISNUMBER(G33),"propulsé",IF(D33="Canon / mitrailleuse / lance-grenade","arme à feu","autre")) -> autre | F33: 500 | M33: =IF(AND(ISNUMBER(G33),ISNUMBER(H33),ISNUMBER(I33),ISNUMBER(F33)),IF(AND(G33>0,H33>0,I33>0,F33>I33),G33*H33/I33*LN(F33/(F33-I33)),"N/A"),"N/A") -> N/A | N33: =IF(ISNUMBER(M33),IF(AND(H33>=$B$7,G33/(F33*$B$9)<$B$8),"croisière","fusée"),"N/A") -> N/A | O33: =IF(N33="fusée",MIN(M33,IF(C33="Jeu de base",$B$4,$B$5)),IF(N33="croisière",$B$6*SQRT(G33),"N/A")) -> N/A | P33: =IF(E33="propulsé",IF(ISNUMBER(O33),IF(AND(ISNUMBER(K33),ISNUMBER(L33)),MEDIAN(K33,L33,O33),IF(ISNUMBER(L33),L33,IF(ISNUMBER(K33),K33,O33))),IF(ISNUMBER(K33),K33,"N/A")),IF(E33="arme à feu",IF(ISNUMBER(J33),IF(ISNUMBER(K33),MIN(J33,K33),J33),"N/A"),"N/A")) -> N/A | Q33: =IF(NOT(ISNUMBER(P33)),"aucune vitesse définie",IF(E33="arme à feu",IF(AND(ISNUMBER(K33),ISNUMBER(J33),K33<J33),"vitesse max fixée (inférieure à la bouche)","vitesse initiale (bouche)"),IF(AND(ISNUMBER(K33),ISNUMBER(L33)),"médiane fichier / wiki / calcul",IF(ISNUMBER(L33),"wiki Delta-V",IF(ISNUMBER(K33),"vitesse fixée du fichier","calcul ("&N33&IF(AND(N33="fusée",M33>O33),", plafonné","")&")"))))) -> aucune vitesse définie | R33: =IF(ISNUMBER(P33),IF(E33="arme à feu",IF($B$10=1,P33,"N/A"),P33),"N/A") -> N/A | S33: =IF(ISNUMBER(R33),ROUND(1+9*(SUMPRODUCT(ISNUMBER($R$21:$R$153)*($R$21:$R$153<=R33))-1)/(COUNT($R$21:$R$153)-1),1),"N/A") -> N/A
A34: =B34&"|"&C34 -> PAB-250LR|Jeu de base | B34: PAB-250LR | C34: Jeu de base | D34: Bombe planante guidée | E34: =IF(ISNUMBER(G34),"propulsé",IF(D34="Canon / mitrailleuse / lance-grenade","arme à feu","autre")) -> autre | F34: 270 | M34: =IF(AND(ISNUMBER(G34),ISNUMBER(H34),ISNUMBER(I34),ISNUMBER(F34)),IF(AND(G34>0,H34>0,I34>0,F34>I34),G34*H34/I34*LN(F34/(F34-I34)),"N/A"),"N/A") -> N/A | N34: =IF(ISNUMBER(M34),IF(AND(H34>=$B$7,G34/(F34*$B$9)<$B$8),"croisière","fusée"),"N/A") -> N/A | O34: =IF(N34="fusée",MIN(M34,IF(C34="Jeu de base",$B$4,$B$5)),IF(N34="croisière",$B$6*SQRT(G34),"N/A")) -> N/A | P34: =IF(E34="propulsé",IF(ISNUMBER(O34),IF(AND(ISNUMBER(K34),ISNUMBER(L34)),MEDIAN(K34,L34,O34),IF(ISNUMBER(L34),L34,IF(ISNUMBER(K34),K34,O34))),IF(ISNUMBER(K34),K34,"N/A")),IF(E34="arme à feu",IF(ISNUMBER(J34),IF(ISNUMBER(K34),MIN(J34,K34),J34),"N/A"),"N/A")) -> N/A | Q34: =IF(NOT(ISNUMBER(P34)),"aucune vitesse définie",IF(E34="arme à feu",IF(AND(ISNUMBER(K34),ISNUMBER(J34),K34<J34),"vitesse max fixée (inférieure à la bouche)","vitesse initiale (bouche)"),IF(AND(ISNUMBER(K34),ISNUMBER(L34)),"médiane fichier / wiki / calcul",IF(ISNUMBER(L34),"wiki Delta-V",IF(ISNUMBER(K34),"vitesse fixée du fichier","calcul ("&N34&IF(AND(N34="fusée",M34>O34),", plafonné","")&")"))))) -> aucune vitesse définie | R34: =IF(ISNUMBER(P34),IF(E34="arme à feu",IF($B$10=1,P34,"N/A"),P34),"N/A") -> N/A | S34: =IF(ISNUMBER(R34),ROUND(1+9*(SUMPRODUCT(ISNUMBER($R$21:$R$153)*($R$21:$R$153<=R34))-1)/(COUNT($R$21:$R$153)-1),1),"N/A") -> N/A
A35: =B35&"|"&C35 -> PAB-80LR|Jeu de base | B35: PAB-80LR | C35: Jeu de base | D35: Bombe planante guidée | E35: =IF(ISNUMBER(G35),"propulsé",IF(D35="Canon / mitrailleuse / lance-grenade","arme à feu","autre")) -> autre | F35: 125 | M35: =IF(AND(ISNUMBER(G35),ISNUMBER(H35),ISNUMBER(I35),ISNUMBER(F35)),IF(AND(G35>0,H35>0,I35>0,F35>I35),G35*H35/I35*LN(F35/(F35-I35)),"N/A"),"N/A") -> N/A | N35: =IF(ISNUMBER(M35),IF(AND(H35>=$B$7,G35/(F35*$B$9)<$B$8),"croisière","fusée"),"N/A") -> N/A | O35: =IF(N35="fusée",MIN(M35,IF(C35="Jeu de base",$B$4,$B$5)),IF(N35="croisière",$B$6*SQRT(G35),"N/A")) -> N/A | P35: =IF(E35="propulsé",IF(ISNUMBER(O35),IF(AND(ISNUMBER(K35),ISNUMBER(L35)),MEDIAN(K35,L35,O35),IF(ISNUMBER(L35),L35,IF(ISNUMBER(K35),K35,O35))),IF(ISNUMBER(K35),K35,"N/A")),IF(E35="arme à feu",IF(ISNUMBER(J35),IF(ISNUMBER(K35),MIN(J35,K35),J35),"N/A"),"N/A")) -> N/A | Q35: =IF(NOT(ISNUMBER(P35)),"aucune vitesse définie",IF(E35="arme à feu",IF(AND(ISNUMBER(K35),ISNUMBER(J35),K35<J35),"vitesse max fixée (inférieure à la bouche)","vitesse initiale (bouche)"),IF(AND(ISNUMBER(K35),ISNUMBER(L35)),"médiane fichier / wiki / calcul",IF(ISNUMBER(L35),"wiki Delta-V",IF(ISNUMBER(K35),"vitesse fixée du fichier","calcul ("&N35&IF(AND(N35="fusée",M35>O35),", plafonné","")&")"))))) -> aucune vitesse définie | R35: =IF(ISNUMBER(P35),IF(E35="arme à feu",IF($B$10=1,P35,"N/A"),P35),"N/A") -> N/A | S35: =IF(ISNUMBER(R35),ROUND(1+9*(SUMPRODUCT(ISNUMBER($R$21:$R$153)*($R$21:$R$153<=R35))-1)/(COUNT($R$21:$R$153)-1),1),"N/A") -> N/A
A36: =B36&"|"&C36 -> Radar Jamming Pod|Jeu de base | B36: Radar Jamming Pod | C36: Jeu de base | D36: Brouilleur (nacelle) | E36: =IF(ISNUMBER(G36),"propulsé",IF(D36="Canon / mitrailleuse / lance-grenade","arme à feu","autre")) -> autre | F36: 0 | J36: 300000000 | K36: 300000000 | M36: =IF(AND(ISNUMBER(G36),ISNUMBER(H36),ISNUMBER(I36),ISNUMBER(F36)),IF(AND(G36>0,H36>0,I36>0,F36>I36),G36*H36/I36*LN(F36/(F36-I36)),"N/A"),"N/A") -> N/A | N36: =IF(ISNUMBER(M36),IF(AND(H36>=$B$7,G36/(F36*$B$9)<$B$8),"croisière","fusée"),"N/A") -> N/A | O36: =IF(N36="fusée",MIN(M36,IF(C36="Jeu de base",$B$4,$B$5)),IF(N36="croisière",$B$6*SQRT(G36),"N/A")) -> N/A | P36: =IF(E36="propulsé",IF(ISNUMBER(O36),IF(AND(ISNUMBER(K36),ISNUMBER(L36)),MEDIAN(K36,L36,O36),IF(ISNUMBER(L36),L36,IF(ISNUMBER(K36),K36,O36))),IF(ISNUMBER(K36),K36,"N/A")),IF(E36="arme à feu",IF(ISNUMBER(J36),IF(ISNUMBER(K36),MIN(J36,K36),J36),"N/A"),"N/A")) -> N/A | Q36: =IF(NOT(ISNUMBER(P36)),"aucune vitesse définie",IF(E36="arme à feu",IF(AND(ISNUMBER(K36),ISNUMBER(J36),K36<J36),"vitesse max fixée (inférieure à la bouche)","vitesse initiale (bouche)"),IF(AND(ISNUMBER(K36),ISNUMBER(L36)),"médiane fichier / wiki / calcul",IF(ISNUMBER(L36),"wiki Delta-V",IF(ISNUMBER(K36),"vitesse fixée du fichier","calcul ("&N36&IF(AND(N36="fusée",M36>O36),", plafonné","")&")"))))) -> aucune vitesse définie | R36: =IF(ISNUMBER(P36),IF(E36="arme à feu",IF($B$10=1,P36,"N/A"),P36),"N/A") -> N/A | S36: =IF(ISNUMBER(R36),ROUND(1+9*(SUMPRODUCT(ISNUMBER($R$21:$R$153)*($R$21:$R$153<=R36))-1)/(COUNT($R$21:$R$153)-1),1),"N/A") -> N/A
A37: =B37&"|"&C37 -> 12.7mm Machine Gun|Jeu de base | B37: 12.7mm Machine Gun | C37: Jeu de base | D37: Canon / mitrailleuse / lance-grenade | E37: =IF(ISNUMBER(G37),"propulsé",IF(D37="Canon / mitrailleuse / lance-grenade","arme à feu","autre")) -> arme à feu | F37: 0.12 | J37: 850 | K37: 850 | M37: =IF(AND(ISNUMBER(G37),ISNUMBER(H37),ISNUMBER(I37),ISNUMBER(F37)),IF(AND(G37>0,H37>0,I37>0,F37>I37),G37*H37/I37*LN(F37/(F37-I37)),"N/A"),"N/A") -> N/A | N37: =IF(ISNUMBER(M37),IF(AND(H37>=$B$7,G37/(F37*$B$9)<$B$8),"croisière","fusée"),"N/A") -> N/A | O37: =IF(N37="fusée",MIN(M37,IF(C37="Jeu de base",$B$4,$B$5)),IF(N37="croisière",$B$6*SQRT(G37),"N/A")) -> N/A | P37: =IF(E37="propulsé",IF(ISNUMBER(O37),IF(AND(ISNUMBER(K37),ISNUMBER(L37)),MEDIAN(K37,L37,O37),IF(ISNUMBER(L37),L37,IF(ISNUMBER(K37),K37,O37))),IF(ISNUMBER(K37),K37,"N/A")),IF(E37="arme à feu",IF(ISNUMBER(J37),IF(ISNUMBER(K37),MIN(J37,K37),J37),"N/A"),"N/A")) -> 850 | Q37: =IF(NOT(ISNUMBER(P37)),"aucune vitesse définie",IF(E37="arme à feu",IF(AND(ISNUMBER(K37),ISNUMBER(J37),K37<J37),"vitesse max fixée (inférieure à la bouche)","vitesse initiale (bouche)"),IF(AND(ISNUMBER(K37),ISNUMBER(L37)),"médiane fichier / wiki / calcul",IF(ISNUMBER(L37),"wiki Delta-V",IF(ISNUMBER(K37),"vitesse fixée du fichier","calcul ("&N37&IF(AND(N37="fusée",M37>O37),", plafonné","")&")"))))) -> vitesse initiale (bouche) | R37: =IF(ISNUMBER(P37),IF(E37="arme à feu",IF($B$10=1,P37,"N/A"),P37),"N/A") -> 850 | S37: =IF(ISNUMBER(R37),ROUND(1+9*(SUMPRODUCT(ISNUMBER($R$21:$R$153)*($R$21:$R$153<=R37))-1)/(COUNT($R$21:$R$153)-1),1),"N/A") -> 4.5
A38: =B38&"|"&C38 -> 12.7mm Rotary Machine Gun|Jeu de base | B38: 12.7mm Rotary Machine Gun | C38: Jeu de base | D38: Canon / mitrailleuse / lance-grenade | E38: =IF(ISNUMBER(G38),"propulsé",IF(D38="Canon / mitrailleuse / lance-grenade","arme à feu","autre")) -> arme à feu | F38: 0.12 | J38: 850 | M38: =IF(AND(ISNUMBER(G38),ISNUMBER(H38),ISNUMBER(I38),ISNUMBER(F38)),IF(AND(G38>0,H38>0,I38>0,F38>I38),G38*H38/I38*LN(F38/(F38-I38)),"N/A"),"N/A") -> N/A | N38: =IF(ISNUMBER(M38),IF(AND(H38>=$B$7,G38/(F38*$B$9)<$B$8),"croisière","fusée"),"N/A") -> N/A | O38: =IF(N38="fusée",MIN(M38,IF(C38="Jeu de base",$B$4,$B$5)),IF(N38="croisière",$B$6*SQRT(G38),"N/A")) -> N/A | P38: =IF(E38="propulsé",IF(ISNUMBER(O38),IF(AND(ISNUMBER(K38),ISNUMBER(L38)),MEDIAN(K38,L38,O38),IF(ISNUMBER(L38),L38,IF(ISNUMBER(K38),K38,O38))),IF(ISNUMBER(K38),K38,"N/A")),IF(E38="arme à feu",IF(ISNUMBER(J38),IF(ISNUMBER(K38),MIN(J38,K38),J38),"N/A"),"N/A")) -> 850 | Q38: =IF(NOT(ISNUMBER(P38)),"aucune vitesse définie",IF(E38="arme à feu",IF(AND(ISNUMBER(K38),ISNUMBER(J38),K38<J38),"vitesse max fixée (inférieure à la bouche)","vitesse initiale (bouche)"),IF(AND(ISNUMBER(K38),ISNUMBER(L38)),"médiane fichier / wiki / calcul",IF(ISNUMBER(L38),"wiki Delta-V",IF(ISNUMBER(K38),"vitesse fixée du fichier","calcul ("&N38&IF(AND(N38="fusée",M38>O38),", plafonné","")&")"))))) -> vitesse initiale (bouche) | R38: =IF(ISNUMBER(P38),IF(E38="arme à feu",IF($B$10=1,P38,"N/A"),P38),"N/A") -> 850 | S38: =IF(ISNUMBER(R38),ROUND(1+9*(SUMPRODUCT(ISNUMBER($R$21:$R$153)*($R$21:$R$153<=R38))-1)/(COUNT($R$21:$R$153)-1),1),"N/A") -> 4.5
A39: =B39&"|"&C39 -> 127mm Cannon|Jeu de base | B39: 127mm Cannon | C39: Jeu de base | D39: Canon / mitrailleuse / lance-grenade | E39: =IF(ISNUMBER(G39),"propulsé",IF(D39="Canon / mitrailleuse / lance-grenade","arme à feu","autre")) -> arme à feu | F39: 32 | J39: 850 | K39: 850 | M39: =IF(AND(ISNUMBER(G39),ISNUMBER(H39),ISNUMBER(I39),ISNUMBER(F39)),IF(AND(G39>0,H39>0,I39>0,F39>I39),G39*H39/I39*LN(F39/(F39-I39)),"N/A"),"N/A") -> N/A | N39: =IF(ISNUMBER(M39),IF(AND(H39>=$B$7,G39/(F39*$B$9)<$B$8),"croisière","fusée"),"N/A") -> N/A | O39: =IF(N39="fusée",MIN(M39,IF(C39="Jeu de base",$B$4,$B$5)),IF(N39="croisière",$B$6*SQRT(G39),"N/A")) -> N/A | P39: =IF(E39="propulsé",IF(ISNUMBER(O39),IF(AND(ISNUMBER(K39),ISNUMBER(L39)),MEDIAN(K39,L39,O39),IF(ISNUMBER(L39),L39,IF(ISNUMBER(K39),K39,O39))),IF(ISNUMBER(K39),K39,"N/A")),IF(E39="arme à feu",IF(ISNUMBER(J39),IF(ISNUMBER(K39),MIN(J39,K39),J39),"N/A"),"N/A")) -> 850 | Q39: =IF(NOT(ISNUMBER(P39)),"aucune vitesse définie",IF(E39="arme à feu",IF(AND(ISNUMBER(K39),ISNUMBER(J39),K39<J39),"vitesse max fixée (inférieure à la bouche)","vitesse initiale (bouche)"),IF(AND(ISNUMBER(K39),ISNUMBER(L39)),"médiane fichier / wiki / calcul",IF(ISNUMBER(L39),"wiki Delta-V",IF(ISNUMBER(K39),"vitesse fixée du fichier","calcul ("&N39&IF(AND(N39="fusée",M39>O39),", plafonné","")&")"))))) -> vitesse initiale (bouche) | R39: =IF(ISNUMBER(P39),IF(E39="arme à feu",IF($B$10=1,P39,"N/A"),P39),"N/A") -> 850 | S39: =IF(ISNUMBER(R39),ROUND(1+9*(SUMPRODUCT(ISNUMBER($R$21:$R$153)*($R$21:$R$153<=R39))-1)/(COUNT($R$21:$R$153)-1),1),"N/A") -> 4.5
A40: =B40&"|"&C40 -> 130mm Cannon|Jeu de base | B40: 130mm Cannon | C40: Jeu de base | D40: Canon / mitrailleuse / lance-grenade | E40: =IF(ISNUMBER(G40),"propulsé",IF(D40="Canon / mitrailleuse / lance-grenade","arme à feu","autre")) -> arme à feu | F40: 30 | J40: 1700 | M40: =IF(AND(ISNUMBER(G40),ISNUMBER(H40),ISNUMBER(I40),ISNUMBER(F40)),IF(AND(G40>0,H40>0,I40>0,F40>I40),G40*H40/I40*LN(F40/(F40-I40)),"N/A"),"N/A") -> N/A | N40: =IF(ISNUMBER(M40),IF(AND(H40>=$B$7,G40/(F40*$B$9)<$B$8),"croisière","fusée"),"N/A") -> N/A | O40: =IF(N40="fusée",MIN(M40,IF(C40="Jeu de base",$B$4,$B$5)),IF(N40="croisière",$B$6*SQRT(G40),"N/A")) -> N/A | P40: =IF(E40="propulsé",IF(ISNUMBER(O40),IF(AND(ISNUMBER(K40),ISNUMBER(L40)),MEDIAN(K40,L40,O40),IF(ISNUMBER(L40),L40,IF(ISNUMBER(K40),K40,O40))),IF(ISNUMBER(K40),K40,"N/A")),IF(E40="arme à feu",IF(ISNUMBER(J40),IF(ISNUMBER(K40),MIN(J40,K40),J40),"N/A"),"N/A")) -> 1700 | Q40: =IF(NOT(ISNUMBER(P40)),"aucune vitesse définie",IF(E40="arme à feu",IF(AND(ISNUMBER(K40),ISNUMBER(J40),K40<J40),"vitesse max fixée (inférieure à la bouche)","vitesse initiale (bouche)"),IF(AND(ISNUMBER(K40),ISNUMBER(L40)),"médiane fichier / wiki / calcul",IF(ISNUMBER(L40),"wiki Delta-V",IF(ISNUMBER(K40),"vitesse fixée du fichier","calcul ("&N40&IF(AND(N40="fusée",M40>O40),", plafonné","")&")"))))) -> vitesse initiale (bouche) | R40: =IF(ISNUMBER(P40),IF(E40="arme à feu",IF($B$10=1,P40,"N/A"),P40),"N/A") -> 1700 | S40: =IF(ISNUMBER(R40),ROUND(1+9*(SUMPRODUCT(ISNUMBER($R$21:$R$153)*($R$21:$R$153<=R40))-1)/(COUNT($R$21:$R$153)-1),1),"N/A") -> 8.8
A41: =B41&"|"&C41 -> 155mm Cannon|Jeu de base | B41: 155mm Cannon | C41: Jeu de base | D41: Canon / mitrailleuse / lance-grenade | E41: =IF(ISNUMBER(G41),"propulsé",IF(D41="Canon / mitrailleuse / lance-grenade","arme à feu","autre")) -> arme à feu | F41: 45 | J41: 850 | K41: 850 | M41: =IF(AND(ISNUMBER(G41),ISNUMBER(H41),ISNUMBER(I41),ISNUMBER(F41)),IF(AND(G41>0,H41>0,I41>0,F41>I41),G41*H41/I41*LN(F41/(F41-I41)),"N/A"),"N/A") -> N/A | N41: =IF(ISNUMBER(M41),IF(AND(H41>=$B$7,G41/(F41*$B$9)<$B$8),"croisière","fusée"),"N/A") -> N/A | O41: =IF(N41="fusée",MIN(M41,IF(C41="Jeu de base",$B$4,$B$5)),IF(N41="croisière",$B$6*SQRT(G41),"N/A")) -> N/A | P41: =IF(E41="propulsé",IF(ISNUMBER(O41),IF(AND(ISNUMBER(K41),ISNUMBER(L41)),MEDIAN(K41,L41,O41),IF(ISNUMBER(L41),L41,IF(ISNUMBER(K41),K41,O41))),IF(ISNUMBER(K41),K41,"N/A")),IF(E41="arme à feu",IF(ISNUMBER(J41),IF(ISNUMBER(K41),MIN(J41,K41),J41),"N/A"),"N/A")) -> 850 | Q41: =IF(NOT(ISNUMBER(P41)),"aucune vitesse définie",IF(E41="arme à feu",IF(AND(ISNUMBER(K41),ISNUMBER(J41),K41<J41),"vitesse max fixée (inférieure à la bouche)","vitesse initiale (bouche)"),IF(AND(ISNUMBER(K41),ISNUMBER(L41)),"médiane fichier / wiki / calcul",IF(ISNUMBER(L41),"wiki Delta-V",IF(ISNUMBER(K41),"vitesse fixée du fichier","calcul ("&N41&IF(AND(N41="fusée",M41>O41),", plafonné","")&")"))))) -> vitesse initiale (bouche) | R41: =IF(ISNUMBER(P41),IF(E41="arme à feu",IF($B$10=1,P41,"N/A"),P41),"N/A") -> 850 | S41: =IF(ISNUMBER(R41),ROUND(1+9*(SUMPRODUCT(ISNUMBER($R$21:$R$153)*($R$21:$R$153<=R41))-1)/(COUNT($R$21:$R$153)-1),1),"N/A") -> 4.5
A42: =B42&"|"&C42 -> 155mm Railgun|Jeu de base | B42: 155mm Railgun | C42: Jeu de base | D42: Canon / mitrailleuse / lance-grenade | E42: =IF(ISNUMBER(G42),"propulsé",IF(D42="Canon / mitrailleuse / lance-grenade","arme à feu","autre")) -> arme à feu | F42: 50 | J42: 2380 | M42: =IF(AND(ISNUMBER(G42),ISNUMBER(H42),ISNUMBER(I42),ISNUMBER(F42)),IF(AND(G42>0,H42>0,I42>0,F42>I42),G42*H42/I42*LN(F42/(F42-I42)),"N/A"),"N/A") -> N/A | N42: =IF(ISNUMBER(M42),IF(AND(H42>=$B$7,G42/(F42*$B$9)<$B$8),"croisière","fusée"),"N/A") -> N/A | O42: =IF(N42="fusée",MIN(M42,IF(C42="Jeu de base",$B$4,$B$5)),IF(N42="croisière",$B$6*SQRT(G42),"N/A")) -> N/A | P42: =IF(E42="propulsé",IF(ISNUMBER(O42),IF(AND(ISNUMBER(K42),ISNUMBER(L42)),MEDIAN(K42,L42,O42),IF(ISNUMBER(L42),L42,IF(ISNUMBER(K42),K42,O42))),IF(ISNUMBER(K42),K42,"N/A")),IF(E42="arme à feu",IF(ISNUMBER(J42),IF(ISNUMBER(K42),MIN(J42,K42),J42),"N/A"),"N/A")) -> 2380 | Q42: =IF(NOT(ISNUMBER(P42)),"aucune vitesse définie",IF(E42="arme à feu",IF(AND(ISNUMBER(K42),ISNUMBER(J42),K42<J42),"vitesse max fixée (inférieure à la bouche)","vitesse initiale (bouche)"),IF(AND(ISNUMBER(K42),ISNUMBER(L42)),"médiane fichier / wiki / calcul",IF(ISNUMBER(L42),"wiki Delta-V",IF(ISNUMBER(K42),"vitesse fixée du fichier","calcul ("&N42&IF(AND(N42="fusée",M42>O42),", plafonné","")&")"))))) -> vitesse initiale (bouche) | R42: =IF(ISNUMBER(P42),IF(E42="arme à feu",IF($B$10=1,P42,"N/A"),P42),"N/A") -> 2380 | S42: =IF(ISNUMBER(R42),ROUND(1+9*(SUMPRODUCT(ISNUMBER($R$21:$R$153)*($R$21:$R$153<=R42))-1)/(COUNT($R$21:$R$153)-1),1),"N/A") -> 9.7
A43: =B43&"|"&C43 -> 20mm Autocannon|Jeu de base | B43: 20mm Autocannon | C43: Jeu de base | D43: Canon / mitrailleuse / lance-grenade | E43: =IF(ISNUMBER(G43),"propulsé",IF(D43="Canon / mitrailleuse / lance-grenade","arme à feu","autre")) -> arme à feu | F43: 0.27 | J43: 1100 | M43: =IF(AND(ISNUMBER(G43),ISNUMBER(H43),ISNUMBER(I43),ISNUMBER(F43)),IF(AND(G43>0,H43>0,I43>0,F43>I43),G43*H43/I43*LN(F43/(F43-I43)),"N/A"),"N/A") -> N/A | N43: =IF(ISNUMBER(M43),IF(AND(H43>=$B$7,G43/(F43*$B$9)<$B$8),"croisière","fusée"),"N/A") -> N/A | O43: =IF(N43="fusée",MIN(M43,IF(C43="Jeu de base",$B$4,$B$5)),IF(N43="croisière",$B$6*SQRT(G43),"N/A")) -> N/A | P43: =IF(E43="propulsé",IF(ISNUMBER(O43),IF(AND(ISNUMBER(K43),ISNUMBER(L43)),MEDIAN(K43,L43,O43),IF(ISNUMBER(L43),L43,IF(ISNUMBER(K43),K43,O43))),IF(ISNUMBER(K43),K43,"N/A")),IF(E43="arme à feu",IF(ISNUMBER(J43),IF(ISNUMBER(K43),MIN(J43,K43),J43),"N/A"),"N/A")) -> 1100 | Q43: =IF(NOT(ISNUMBER(P43)),"aucune vitesse définie",IF(E43="arme à feu",IF(AND(ISNUMBER(K43),ISNUMBER(J43),K43<J43),"vitesse max fixée (inférieure à la bouche)","vitesse initiale (bouche)"),IF(AND(ISNUMBER(K43),ISNUMBER(L43)),"médiane fichier / wiki / calcul",IF(ISNUMBER(L43),"wiki Delta-V",IF(ISNUMBER(K43),"vitesse fixée du fichier","calcul ("&N43&IF(AND(N43="fusée",M43>O43),", plafonné","")&")"))))) -> vitesse initiale (bouche) | R43: =IF(ISNUMBER(P43),IF(E43="arme à feu",IF($B$10=1,P43,"N/A"),P43),"N/A") -> 1100 | S43: =IF(ISNUMBER(R43),ROUND(1+9*(SUMPRODUCT(ISNUMBER($R$21:$R$153)*($R$21:$R$153<=R43))-1)/(COUNT($R$21:$R$153)-1),1),"N/A") -> 7.1
A44: =B44&"|"&C44 -> 20mm Rotary Cannon (variante 1)|Jeu de base | B44: 20mm Rotary Cannon (variante 1) | C44: Jeu de base | D44: Canon / mitrailleuse / lance-grenade | E44: =IF(ISNUMBER(G44),"propulsé",IF(D44="Canon / mitrailleuse / lance-grenade","arme à feu","autre")) -> arme à feu | F44: 0.27 | J44: 1100 | M44: =IF(AND(ISNUMBER(G44),ISNUMBER(H44),ISNUMBER(I44),ISNUMBER(F44)),IF(AND(G44>0,H44>0,I44>0,F44>I44),G44*H44/I44*LN(F44/(F44-I44)),"N/A"),"N/A") -> N/A | N44: =IF(ISNUMBER(M44),IF(AND(H44>=$B$7,G44/(F44*$B$9)<$B$8),"croisière","fusée"),"N/A") -> N/A | O44: =IF(N44="fusée",MIN(M44,IF(C44="Jeu de base",$B$4,$B$5)),IF(N44="croisière",$B$6*SQRT(G44),"N/A")) -> N/A | P44: =IF(E44="propulsé",IF(ISNUMBER(O44),IF(AND(ISNUMBER(K44),ISNUMBER(L44)),MEDIAN(K44,L44,O44),IF(ISNUMBER(L44),L44,IF(ISNUMBER(K44),K44,O44))),IF(ISNUMBER(K44),K44,"N/A")),IF(E44="arme à feu",IF(ISNUMBER(J44),IF(ISNUMBER(K44),MIN(J44,K44),J44),"N/A"),"N/A")) -> 1100 | Q44: =IF(NOT(ISNUMBER(P44)),"aucune vitesse définie",IF(E44="arme à feu",IF(AND(ISNUMBER(K44),ISNUMBER(J44),K44<J44),"vitesse max fixée (inférieure à la bouche)","vitesse initiale (bouche)"),IF(AND(ISNUMBER(K44),ISNUMBER(L44)),"médiane fichier / wiki / calcul",IF(ISNUMBER(L44),"wiki Delta-V",IF(ISNUMBER(K44),"vitesse fixée du fichier","calcul ("&N44&IF(AND(N44="fusée",M44>O44),", plafonné","")&")"))))) -> vitesse initiale (bouche) | R44: =IF(ISNUMBER(P44),IF(E44="arme à feu",IF($B$10=1,P44,"N/A"),P44),"N/A") -> 1100 | S44: =IF(ISNUMBER(R44),ROUND(1+9*(SUMPRODUCT(ISNUMBER($R$21:$R$153)*($R$21:$R$153<=R44))-1)/(COUNT($R$21:$R$153)-1),1),"N/A") -> 7.1
...
